Workbook

Sheet Dashboard
A1: TAXI24 GLOBAL — Dashboard Financiero Ejecutivo
A2: Resumen del modelo | Escenario Base | Vinculado a todas las hojas
A4: KPIs PRINCIPALES (Año 3)
A5: Ingresos Totales Año 3 | B5: ='P&L'!D14 -> 13644384
A6: EBITDA Año 3 | B6: ='P&L'!D31 -> 9354761.5
A7: Utilidad Neta Año 3 | B7: ='P&L'!D40 -> 8365285.3
A8: GMV Año 3 | B8: ='P&L'!D8 -> 65598000
A9: Conductores activos Año 3 | B9: ='P&L'!D44 -> 126150
A11: INVERSIÓN REQUERIDA
A12: Inversión inicial total | B12: =Assumptions!B62 -> 800000
A13: Caja acumulada fin Año 5 | B13: =CashFlow!F21 -> 69949317
A15: RESUMEN POR AÑO — INGRESOS Y EBITDA
A16: Métrica | B16: 2027 | C16: 2028 | D16: 2029 | E16: 2030 | F16: 2031
A17: Ingresos | B17: ='P&L'!B14 -> 1297920 | C17: ='P&L'!C14 -> 4704960 | D17: ='P&L'!D14 -> 13644384 | E17: ='P&L'!E14 -> 29676535 | F17: ='P&L'!F14 -> 63112098
A18: EBITDA | B18: ='P&L'!B31 -> 505920 | C18: ='P&L'!C31 -> 2900810 | D18: ='P&L'!D31 -> 9354761.5 | E18: ='P&L'!E31 -> 21010519 | F18: ='P&L'!F31 -> 45491256
A19: Utilidad Neta | B19: ='P&L'!B40 -> 433124 | C19: ='P&L'!C40 -> 2618145.2 | D19: ='P&L'!D40 -> 8365285.3 | E19: ='P&L'!E40 -> 18432057 | F19: ='P&L'!F40 -> 39970705
A20: Caja acumulada | B20: =CashFlow!B21 -> 983124 | C20: =CashFlow!C21 -> 3536269.2 | D20: =CashFlow!D21 -> 11811555 | E20: =CashFlow!E21 -> 30128612 | F20: =CashFlow!F21 -> 69949317
A22: Cómo usar este modelo:
A23: 1. Ve a la hoja 'Assumptions' y modifica las celdas en AZUL / AMARILLO según tus supuestos.
A24: 2. Todas las demás hojas se actualizan automáticamente mediante fórmulas.
A25: 3. Revisa P&L, CashFlow y UnitEconomics para el detalle.
A26: 4. El escenario es conservador. Puedes crear copias del archivo para escenarios optimista/pesimista.

Sheet Assumptions
A1: TAXI24 GLOBAL — Modelo Financiero Completo
A2: Fecha de modelo: 2026-10-11 | Escenario Base | Moneda: USD
A3: Instrucciones: Celdas en AZUL = inputs editables. Celdas en AMARILLO = supuestos clave. Fórmulas en NEGRO. No modificar fórmulas.
A5: 1. SUPUESTOS GENERALES Y ESTRUCTURA
A6: Parámetro | B6: Valor | C6: Notas / Fuente
A7: Año de inicio | B7: 2027 | C7: Año fiscal de lanzamiento
A8: Moneda del modelo | B8: USD | C8: Todas las cifras en dólares americanos
A9: Horizonte de proyección | B9: 5 | C9: Años
A10: Tasa de cambio COP/USD (ref) | B10: 4200 | C10: Referencia Colombia
A11: Inflación anual promedio | B11: 0.04 | C11: Ajuste de costos
A13: 2. MERCADO Y CRECIMIENTO (VOLUMEN)
A14: Parámetro | B14: Valor | C14: Notas
A15: Ciudades Año 1 | B15: 2 | C15: Colombia + Panamá piloto
A16: Ciudades Año 2 | B16: 5
A17: Ciudades Año 3 | B17: 10
A18: Ciudades Año 4 | B18: 15
A19: Ciudades Año 5 | B19: 22 | C19: Incluye expansión UE / México / otros
A20: Viajes promedio / ciudad / mes - Año 1 | B20: 40000 | C20: Conservador para arranque
A21: Crecimiento viajes por ciudad (anual) | B21: 0.45 | C21: Crecimiento orgánico + densidad
A22: Factor estacionalidad (promedio) | B22: 1 | C22: Ajuste anual
A25: 3. UNIT ECONOMICS (POR VIAJE)
A26: Parámetro | B26: Valor | C26: Notas
A27: Tarifa promedio bruta por viaje (USD) | B27: 6.5 | C27: Promedio LatAm mixto
A28: Take rate bruto (comisión) | B28: 0.22 | C28: Antes de incentivos
A29: Incentivos / promociones (% GMV) | B29: 0.04 | C29: Costo de adquisición/retención
A30: Take rate neto | B30: 0.18 | C30: Después de incentivos (calculado)
A31: Costo variable por viaje (maps, pago, SMS) | B31: 0.35 | C31: USD por viaje
A32: Contribution margin por viaje | B32: 0.82 | C32: Calculado: take neto - costo var
A35: 4. CONDUCTORES Y FUERZA LABORAL
A36: Parámetro | B36: Valor | C36: Notas
A37: Viajes promedio por conductor / mes | B37: 80 | C37: Part-time + full-time mix
A38: Costo adquisición conductor (CAC) | B38: 45 | C38: USD por conductor activado
A39: % churn mensual conductores | B39: 0.08 | C39: Rotación
A40: Ingreso neto conductor / viaje | B40: 5.2 | C40: Después de comisión plataforma
A43: 5. COSTOS OPERATIVOS FIJOS (ANUALES BASE)
A44: Concepto | B44: Año 1 (USD) | C44: Crecimiento anual
A45: Personal (tech + ops + soporte) | B45: 180000 | C45: 0.35
A46: Infraestructura cloud / servidores | B46: 36000 | C46: 0.4
A47: Marketing & adquisición usuarios | B47: 120000 | C47: 0.3
A48: Legal, compliance, licencias | B48: 45000 | C48: 0.15
...

Sheet P&L
A1: TAXI24 GLOBAL — Estado de Resultados (P&L) Proyectado
A2: Cifras en USD | Escenario Base | Vinculado a Assumptions
A4: Concepto | B4: 2027 | C4: 2028 | D4: 2029 | E4: 2030 | F4: 2031
A5: VOLUMEN
A6: Ciudades activas | B6: =Assumptions!B15 -> 2 | C6: =Assumptions!B16 -> 5 | D6: =Assumptions!B17 -> 10 | E6: =Assumptions!B18 -> 15 | F6: =Assumptions!B19 -> 22
A7: Viajes anuales (miles) | B7: =Assumptions!B15*Assumptions!B20*12/1000 -> 960 | C7: =C6*Assumptions!B20*(1+Assumptions!B21)*12/1000 -> 3480 | D7: =D6*Assumptions!B20*(1+Assumptions!B21)^2*12/1000 -> 10092 | E7: =E6*Assumptions!B20*(1+Assumptions!B21)^3*12/1000 -> 21950.1 | F7: =F6*Assumptions!B20*(1+Assumptions!B21)^4*12/1000 -> 46680.546
A8: GMV (Gross Merchandise Value) | B8: =B7*1000*Assumptions!B27 -> 6240000 | C8: =C7*1000*Assumptions!B27 -> 22620000 | D8: =D7*1000*Assumptions!B27 -> 65598000 | E8: =E7*1000*Assumptions!B27 -> 142675650 | F8: =F7*1000*Assumptions!B27 -> 303423549
A10: INGRESOS
A11: Comisiones netas (take rate neto) | B11: =B8*Assumptions!B30 -> 1123200 | C11: =C8*Assumptions!B30 -> 4071600 | D11: =D8*Assumptions!B30 -> 11807640 | E11: =E8*Assumptions!B30 -> 25681617 | F11: =F8*Assumptions!B30 -> 54616239
A12: Suscripciones B2B / flotas | B12: =B8*Assumptions!B67 -> 93600 | C12: =C8*Assumptions!B67 -> 339300 | D12: =D8*Assumptions!B67 -> 983970 | E12: =E8*Assumptions!B67 -> 2140134.8 | F12: =F8*Assumptions!B67 -> 4551353.2
A13: Servicios empresariales + integraciones | B13: =B8*(Assumptions!B68+Assumptions!B69) -> 81120 | C13: =C8*(Assumptions!B68+Assumptions!B69) -> 294060 | D13: =D8*(Assumptions!B68+Assumptions!B69) -> 852774 | E13: =E8*(Assumptions!B68+Assumptions!B69) -> 1854783.4 | F13: =F8*(Assumptions!B68+Assumptions!B69) -> 3944506.1
A14: TOTAL INGRESOS | B14: =B11+B12+B13 -> 1297920 | C14: =C11+C12+C13 -> 4704960 | D14: =D11+D12+D13 -> 13644384 | E14: =E11+E12+E13 -> 29676535 | F14: =F11+F12+F13 -> 63112098
A16: COSTOS VARIABLES
A17: Costos variables por viaje (maps, pagos, SMS) | B17: =B7*1000*Assumptions!B31 -> 336000 | C17: =C7*1000*Assumptions!B31 -> 1218000 | D17: =D7*1000*Assumptions!B31 -> 3532200 | E17: =E7*1000*Assumptions!B31 -> 7682535 | F17: =F7*1000*Assumptions!B31 -> 16338191
A18: Contribution Margin | B18: =B14-B17 -> 961920 | C18: =C14-C17 -> 3486960 | D18: =D14-D17 -> 10112184 | E18: =E14-E17 -> 21994000 | F18: =F14-F17 -> 46773907
A19: Contribution Margin % | B19: =IF(B14=0,0,B18/B14) -> 0.74112426 | C19: =IF(C14=0,0,C18/C14) -> 0.74112426 | D19: =IF(D14=0,0,D18/D14) -> 0.74112426 | E19: =IF(E14=0,0,E18/E14) -> 0.74112426 | F19: =IF(F14=0,0,F18/F14) -> 0.74112426
A21: GASTOS OPERATIVOS (OpEx)
A22: Personal (tech + ops + soporte) | B22: =Assumptions!B45 -> 180000 | C22: =B22*(1+Assumptions!C45) -> 243000 | D22: =C22*(1+Assumptions!C45) -> 328050 | E22: =D22*(1+Assumptions!C45) -> 442867.5 | F22: =E22*(1+Assumptions!C45) -> 597871.12
A23: Infraestructura cloud | B23: =Assumptions!B46 -> 36000 | C23: =B23*(1+Assumptions!C46) -> 50400 | D23: =C23*(1+Assumptions!C46) -> 70560 | E23: =D23*(1+Assumptions!C46) -> 98784 | F23: =E23*(1+Assumptions!C46) -> 138297.6
A24: Marketing & adquisición | B24: =Assumptions!B47 -> 120000 | C24: =B24*(1+Assumptions!C47) -> 156000 | D24: =C24*(1+Assumptions!C47) -> 202800 | E24: =D24*(1+Assumptions!C47) -> 263640 | F24: =E24*(1+Assumptions!C47) -> 342732
A25: Legal, compliance, licencias | B25: =Assumptions!B48 -> 45000 | C25: =B25*(1+Assumptions!C48) -> 51750 | D25: =C25*(1+Assumptions!C48) -> 59512.5 | E25: =D25*(1+Assumptions!C48) -> 68439.375 | F25: =E25*(1+Assumptions!C48) -> 78705.281
A26: Seguros | B26: =Assumptions!B49 -> 25000 | C26: =B26*(1+Assumptions!C49) -> 30000 | D26: =C26*(1+Assumptions!C49) -> 36000 | E26: =D26*(1+Assumptions!C49) -> 43200 | F26: =E26*(1+Assumptions!C49) -> 51840
A27: Oficinas / admin | B27: =Assumptions!B50 -> 30000 | C27: =B27*(1+Assumptions!C50) -> 33000 | D27: =C27*(1+Assumptions!C50) -> 36300 | E27: =D27*(1+Assumptions!C50) -> 39930 | F27: =E27*(1+Assumptions!C50) -> 43923
A28: Contingencia | B28: =Assumptions!B51 -> 20000 | C28: =B28*(1+Assumptions!C51) -> 22000 | D28: =C28*(1+Assumptions!C51) -> 24200 | E28: =D28*(1+Assumptions!C51) -> 26620 | F28: =E28*(1+Assumptions!C51) -> 29282
A29: TOTAL OpEx | B29: =SUM(B22:B28) -> 456000 | C29: =SUM(C22:C28) -> 586150 | D29: =SUM(D22:D28) -> 757422.5 | E29: =SUM(E22:E28) -> 983480.88 | F29: =SUM(F22:F28) -> 1282651
A31: EBITDA | B31: =B18-B29 -> 505920 | C31: =C18-C29 -> 2900810 | D31: =D18-D29 -> 9354761.5 | E31: =E18-E29 -> 21010519 | F31: =F18-F29 -> 45491256
A32: EBITDA Margin % | B32: =IF(B14=0,0,B31/B14) -> 0.3897929 | C32: =IF(C14=0,0,C31/C14) -> 0.61654297 | D32: =IF(D14=0,0,D31/D14) -> 0.68561259 | E32: =IF(E14=0,0,E31/E14) -> 0.70798424 | F32: =IF(F14=0,0,F31/F14) -> 0.72080088
A34: Depreciación & Amortización (simplificada) | B34: 50000 | C34: 55000 | D34: 60000 | E34: 65000 | F34: 70000
A35: EBIT | B35: =B31-B34 -> 455920 | C35: =C31-C34 -> 2845810 | D35: =D31-D34 -> 9294761.5 | E35: =E31-E34 -> 20945519 | F35: =F31-F34 -> 45421256
A37: Impuestos (tasa efectiva asumida) | B37: 0.05 | C37: 0.08 | D37: 0.1 | E37: 0.12 | F37: 0.12
A38: Impuesto sobre la renta | B38: =MAX(0,B35)*B37 -> 22796 | C38: =MAX(0,C35)*C37 -> 227664.8 | D38: =MAX(0,D35)*D37 -> 929476.15 | E38: =MAX(0,E35)*E37 -> 2513462.3 | F38: =MAX(0,F35)*F37 -> 5450550.7
A40: UTILIDAD NETA | B40: =B35-B38 -> 433124 | C40: =C35-C38 -> 2618145.2 | D40: =D35-D38 -> 8365285.3 | E40: =E35-E38 -> 18432057 | F40: =F35-F38 -> 39970705
A41: Net Margin % | B41: =IF(B14=0,0,B40/B14) -> 0.33370624 | C41: =IF(C14=0,0,C40/C14) -> 0.55646492 | D41: =IF(D14=0,0,D40/D14) -> 0.61309366 | E41: =IF(E14=0,0,E40/E14) -> 0.62109869 | F41: =IF(F14=0,0,F40/F14) -> 0.63332874
A43: IMPACTO EN CONDUCTORES
A44: Conductores activos (promedio) | B44: =B7*1000/Assumptions!B37 -> 12000 | C44: =C7*1000/Assumptions!B37 -> 43500 | D44: =D7*1000/Assumptions!B37 -> 126150 | E44: =E7*1000/Assumptions!B37 -> 274376.25 | F44: =F7*1000/Assumptions!B37 -> 583506.82
A45: Ingresos brutos conductores (estimado) | B45: =B7*1000*Assumptions!B40 -> 4992000 | C45: =C7*1000*Assumptions!B40 -> 18096000 | D45: =D7*1000*Assumptions!B40 -> 52478400 | E45: =E7*1000*Assumptions!B40 -> 114140520 | F45: =F7*1000*Assumptions!B40 -> 2.4273884e+08

Sheet CashFlow
A1: TAXI24 GLOBAL — Flujo de Caja Proyectado
A2: Cifras en USD | Escenario Base
A4: Concepto | B4: 2027 | C4: 2028 | D4: 2029 | E4: 2030 | F4: 2031
A5: UTILIDAD NETA | B5: ='P&L'!B40 -> 433124 | C5: ='P&L'!C40 -> 2618145.2 | D5: ='P&L'!D40 -> 8365285.3 | E5: ='P&L'!E40 -> 18432057 | F5: ='P&L'!F40 -> 39970705
A6: (+) Depreciación & Amortización | B6: ='P&L'!B34 -> 50000 | C6: ='P&L'!C34 -> 55000 | D6: ='P&L'!D34 -> 60000 | E6: ='P&L'!E34 -> 65000 | F6: ='P&L'!F34 -> 70000
A7: Cash Flow Operativo | B7: =B5+B6 -> 483124 | C7: =C5+C6 -> 2673145.2 | D7: =D5+D6 -> 8425285.3 | E7: =E5+E6 -> 18497057 | F7: =F5+F6 -> 40040705
A9: INVERSIONES (CapEx)
A10: Inversión inicial / CapEx tecnológico | B10: =-Assumptions!B56 -> -250000 | C10: -40000 | D10: -50000 | E10: -60000 | F10: -70000
A11: Otras inversiones / expansión | B11: -50000 | C11: -80000 | D11: -100000 | E11: -120000 | F11: -150000
A12: Total CapEx | B12: =B10+B11 -> -300000 | C12: =C10+C11 -> -120000 | D12: =D10+D11 -> -150000 | E12: =E10+E11 -> -180000 | F12: =F10+F11 -> -220000
A14: FINANCIAMIENTO
A15: Aporte de capital (equity) | B15: =Assumptions!B62 -> 800000 | C15: 0 | D15: 0 | E15: 0 | F15: 0
A16: Deuda neta (nueva - amortización) | B16: 0 | C16: 0 | D16: 0 | E16: 0 | F16: 0
A17: Total Financiamiento | B17: =B15+B16 -> 800000 | C17: =C15+C16 -> 0 | D17: =D15+D16 -> 0 | E17: =E15+E16 -> 0 | F17: =F15+F16 -> 0
A19: FLUJO DE CAJA NETO DEL PERÍODO | B19: =B7+B12+B17 -> 983124 | C19: =C7+C12+C17 -> 2553145.2 | D19: =D7+D12+D17 -> 8275285.3 | E19: =E7+E12+E17 -> 18317057 | F19: =F7+F12+F17 -> 39820705
A21: Caja acumulada (fin de año) | B21: =B19 -> 983124 | C21: =B21+C19 -> 3536269.2 | D21: =C21+D19 -> 11811555 | E21: =D21+E19 -> 30128612 | F21: =E21+F19 -> 69949317

Sheet UnitEconomics
A1: TAXI24 GLOBAL — Unit Economics & KPIs
A3: MÉTRICAS POR VIAJE
A4: Métrica | B4: Valor | C4: Fórmula / Nota
A5: Tarifa promedio bruta | B5: =Assumptions!B27 -> 6.5 | C5: Input Assumptions
A6: Comisión bruta (take rate) | B6: =Assumptions!B28 -> 0.22 | C6: Input
A7: Incentivos % GMV | B7: =Assumptions!B29 -> 0.04 | C7: Input
A8: Take rate neto | B8: =Assumptions!B30 -> 0.18 | C8: Después de incentivos
A9: Ingreso plataforma por viaje | B9: =B5*B8 -> 1.17 | C9: Tarifa × take rate neto
A10: Costo variable por viaje | B10: =Assumptions!B31 -> 0.35 | C10: Maps, pagos, SMS
A11: Contribution Margin por viaje | B11: =B9-B10 -> 0.82 | C11: Ingreso neto - costo variable
A12: CM % | B12: =IF(B9=0,0,B11/B9) -> 0.7008547 | C12: Margen de contribución
A14: MÉTRICAS POR CONDUCTOR
A15: Viajes / conductor / mes | B15: =Assumptions!B37 -> 80
A16: Ingreso conductor / viaje | B16: =Assumptions!B40 -> 5.2
A17: Ingreso conductor / mes | B17: =B15*B16 -> 416
A18: CAC Conductor | B18: =Assumptions!B38 -> 45
A19: Payback CAC (meses) | B19: =IF(B11=0,0,B18/(B11*B15)) -> 0.68597561
A21: KPIs CLAVE DE NEGOCIO
A22: LTV / CAC (aproximado, asumir 18 meses vida) | B22: =IF(B18=0,0,(B11*B15*18)/B18) -> 26.24

Sheet Investment
A1: TAXI24 GLOBAL — Resumen de Inversión y Uso de Fondos
A3: USO DE FONDOS (INVERSIÓN INICIAL)
A4: Concepto | B4: Monto USD | C4: % | D4: Descripción
A5: Desarrollo tecnología (App + Backend + IA) | B5: =Assumptions!B56 -> 250000 | C5: =Assumptions!C56 -> 0.3125 | D5: Propiedad de Estonia OÜ
A6: Capital de trabajo operativo (6 meses) | B6: =Assumptions!B57 -> 180000 | C6: =Assumptions!C57 -> 0.225 | D6: Personal, cloud, ops iniciales
A7: Adquisición inicial conductores | B7: =Assumptions!B58 -> 120000 | C7: =Assumptions!C58 -> 0.15 | D7: Bonos, onboarding, incentivos
A8: Marketing lanzamiento | B8: =Assumptions!B59 -> 100000 | C8: =Assumptions!C59 -> 0.125 | D8: Usuarios + awareness
A9: Legal, constitución holding, compliance | B9: =Assumptions!B60 -> 60000 | C9: =Assumptions!C60 -> 0.075 | D9: Estonia + Panamá + Colombia
A10: Reserva / contingencia | B10: =Assumptions!B61 -> 90000 | C10: =Assumptions!C61 -> 0.1125 | D10: Buffer de seguridad
A11: TOTAL | B11: =Assumptions!B62 -> 800000 | C11: 1
A14: ESTRUCTURA DE CAPITAL RECOMENDADA
A15: Ronda | B15: Monto objetivo | C15: Uso principal
A16: Pre-Seed / Seed | B16: 800000 | C16: MVP + piloto Colombia/Panamá + holding setup
A17: Series A (Año 2-3) | B17: 3000000 | C17: Expansión multi-país + equipo + marketing
A19: NOTAS IMPORTANTES
A20: 1. El holding en Estonia permite reinvertir utilidades sin impuesto corporativo hasta distribución.
A21: 2. Panamá actúa como holding regional con 0% sobre ingresos de fuente extranjera.
A22: 3. Los números son estimaciones conservadoras. Ajustar supuestos en la hoja Assumptions.
A23: 4. Se recomienda validar unit economics en piloto antes de escalar capital.
